DEBUG 2018-07-30 13:56:28,378 utils 23460 19432 (0.001) SELECT @@SQL_AUTO_IS_NULL; args=None
DEBUG 2018-07-30 13:56:28,379 utils 23460 19432 (0.001) SELECT VERSION(); args=None
DEBUG 2018-07-30 13:56:28,394 utils 23460 19432 (0.001) SELECT `django_session`.`session_key`, `django_session`.`session_data`, `django_session`.`expire_date` FROM `django_session` WHERE (`django_session`.`session_key` = '3yyd3kqtqc9xvorgka26zkt1fxdn9qdq' AND `django_session`.`expire_date` > '2018-07-30 04:56:28.358365'); args=('3yyd3kqtqc9xvorgka26zkt1fxdn9qdq', '2018-07-30 04:56:28.358365')
DEBUG 2018-07-30 13:56:28,398 utils 23460 19432 (0.002) SELECT `auth_user`.`id`, `auth_user`.`password`, `auth_user`.`last_login`, `auth_user`.`is_superuser`, `auth_user`.`username`, `auth_user`.`first_name`, `auth_user`.`last_name`, `auth_user`.`email`, `auth_user`.`is_staff`, `auth_user`.`is_active`, `auth_user`.`date_joined` FROM `auth_user` WHERE `auth_user`.`id` = 1; args=(1,)
DEBUG 2018-07-30 13:56:28,402 base 23460 19432 Exception while resolving variable 'qry' in template 'tblCpy_list.html'.
Traceback (most recent call last):
  File "c:\Lang\django1\myenv\lib\site-packages\django\utils\datastructures.py", line 83, in __getitem__
    list_ = super(MultiValueDict, self).__getitem__(key)
KeyError: 'qry'

During handling of the above exception, another exception occurred:

Traceback (most recent call last):
  File "c:\Lang\django1\myenv\lib\site-packages\django\template\base.py", line 882, in _resolve_lookup
    current = current[bit]
  File "c:\Lang\django1\myenv\lib\site-packages\django\utils\datastructures.py", line 85, in __getitem__
    raise MultiValueDictKeyError(repr(key))
django.utils.datastructures.MultiValueDictKeyError: "'qry'"

During handling of the above exception, another exception occurred:

Traceback (most recent call last):
  File "c:\Lang\django1\myenv\lib\site-packages\django\template\base.py", line 890, in _resolve_lookup
    current = getattr(current, bit)
AttributeError: 'QueryDict' object has no attribute 'qry'

During handling of the above exception, another exception occurred:

Traceback (most recent call last):
  File "c:\Lang\django1\myenv\lib\site-packages\django\template\base.py", line 896, in _resolve_lookup
    current = current[int(bit)]
ValueError: invalid literal for int() with base 10: 'qry'

During handling of the above exception, another exception occurred:

Traceback (most recent call last):
  File "c:\Lang\django1\myenv\lib\site-packages\django\template\base.py", line 903, in _resolve_lookup
    (bit, current))  # missing attribute
django.template.base.VariableDoesNotExist: Failed lookup for key [qry] in '<QueryDict: {}>'
DEBUG 2018-07-30 13:56:28,408 utils 23460 19432 (0.002) SELECT `dq_tablecopy`.`TABLE_NO`, `dq_tablecopy`.`TABLE_NM`, `dq_tablecopy`.`TABLE_HANGL_NM`, `dq_tablecopy`.`TABLE_COPY_EXPLN`, `dq_tablecopy`.`USE_YN`, `dq_tablecopy`.`RGSTR_ID`, `dq_tablecopy`.`RGST_DTTM`, `dq_tablecopy`.`MODR_ID`, `dq_tablecopy`.`MODI_DTTM` FROM `dq_tablecopy`; args=()
INFO 2018-07-30 13:56:28,675 basehttp 23460 19432 "GET /dq/tblCpys HTTP/1.1" 200 15764
