ERROR Internal Server Error: /dq/vrfy/tasks/
Traceback (most recent call last):
  File "c:\Lang\django1\myenv\lib\site-packages\django\utils\datastructures.py", line 83, in __getitem__
    list_ = super(MultiValueDict, self).__getitem__(key)
KeyError: 'env'

During handling of the above exception, another exception occurred:

Traceback (most recent call last):
  File "c:\Lang\django1\myenv\lib\site-packages\django\core\handlers\exception.py", line 41, in inner
    response = get_response(request)
  File "c:\Lang\django1\myenv\lib\site-packages\django\core\handlers\base.py", line 187, in _get_response
    response = self.process_exception_by_middleware(e, request)
  File "c:\Lang\django1\myenv\lib\site-packages\django\core\handlers\base.py", line 185, in _get_response
    response = wrapped_callback(request, *callback_args, **callback_kwargs)
  File "c:\Lang\django1\myenv\lib\site-packages\django\views\decorators\csrf.py", line 58, in wrapped_view
    return view_func(*args, **kwargs)
  File "c:\Lang\django1\mysite\dq\views.py", line 170, in vrfy_tasks
    en = request.GET['env']
  File "c:\Lang\django1\myenv\lib\site-packages\django\utils\datastructures.py", line 85, in __getitem__
    raise MultiValueDictKeyError(repr(key))
django.utils.datastructures.MultiValueDictKeyError: "'env'"
ERROR Internal Server Error: /dq/vrfy/tasks/
Traceback (most recent call last):
  File "c:\Lang\django1\myenv\lib\site-packages\django\utils\datastructures.py", line 83, in __getitem__
    list_ = super(MultiValueDict, self).__getitem__(key)
KeyError: 'env'

During handling of the above exception, another exception occurred:

Traceback (most recent call last):
  File "c:\Lang\django1\myenv\lib\site-packages\django\core\handlers\exception.py", line 41, in inner
    response = get_response(request)
  File "c:\Lang\django1\myenv\lib\site-packages\django\core\handlers\base.py", line 187, in _get_response
    response = self.process_exception_by_middleware(e, request)
  File "c:\Lang\django1\myenv\lib\site-packages\django\core\handlers\base.py", line 185, in _get_response
    response = wrapped_callback(request, *callback_args, **callback_kwargs)
  File "c:\Lang\django1\myenv\lib\site-packages\django\views\decorators\csrf.py", line 58, in wrapped_view
    return view_func(*args, **kwargs)
  File "c:\Lang\django1\mysite\dq\views.py", line 170, in vrfy_tasks
    env = request.GET['env']
  File "c:\Lang\django1\myenv\lib\site-packages\django\utils\datastructures.py", line 85, in __getitem__
    raise MultiValueDictKeyError(repr(key))
django.utils.datastructures.MultiValueDictKeyError: "'env'"
ERROR Internal Server Error: /dq/vrfy/tasks/
Traceback (most recent call last):
  File "c:\Lang\django1\myenv\lib\site-packages\django\core\handlers\exception.py", line 41, in inner
    response = get_response(request)
  File "c:\Lang\django1\myenv\lib\site-packages\django\core\handlers\base.py", line 187, in _get_response
    response = self.process_exception_by_middleware(e, request)
  File "c:\Lang\django1\myenv\lib\site-packages\django\core\handlers\base.py", line 185, in _get_response
    response = wrapped_callback(request, *callback_args, **callback_kwargs)
  File "c:\Lang\django1\myenv\lib\site-packages\django\views\decorators\csrf.py", line 58, in wrapped_view
    return view_func(*args, **kwargs)
  File "c:\Lang\django1\mysite\dq\views.py", line 178, in vrfy_tasks
    , 'env'  : env
UnboundLocalError: local variable 'env' referenced before assignment
